[2024-04-20T13:17:55.996+0000] {local_task_job_runner.py:120} INFO - ::group::Pre task execution logs
[2024-04-20T13:17:56.024+0000] {taskinstance.py:2073} INFO - Dependencies all met for dep_context=non-requeueable deps ti=<TaskInstance: profile_creation_dag.create_profiles manual__2024-04-20T13:17:53.069327+00:00 [queued]>
[2024-04-20T13:17:56.033+0000] {taskinstance.py:2073} INFO - Dependencies all met for dep_context=requeueable deps ti=<TaskInstance: profile_creation_dag.create_profiles manual__2024-04-20T13:17:53.069327+00:00 [queued]>
[2024-04-20T13:17:56.033+0000] {taskinstance.py:2303} INFO - Starting attempt 1 of 1
[2024-04-20T13:17:56.043+0000] {taskinstance.py:2327} INFO - Executing <Task(PythonOperator): create_profiles> on 2024-04-20 13:17:53.069327+00:00
[2024-04-20T13:17:56.051+0000] {warnings.py:110} WARNING - /home/***/.local/lib/python3.12/site-packages/***/task/task_runner/standard_task_runner.py:61: DeprecationWarning: This process (pid=114) is multi-threaded, use of fork() may lead to deadlocks in the child.
  pid = os.fork()

[2024-04-20T13:17:56.052+0000] {standard_task_runner.py:63} INFO - Started process 116 to run task
[2024-04-20T13:17:56.053+0000] {standard_task_runner.py:90} INFO - Running: ['***', 'tasks', 'run', 'profile_creation_dag', 'create_profiles', 'manual__2024-04-20T13:17:53.069327+00:00', '--job-id', '4', '--raw', '--subdir', 'DAGS_FOLDER/sample-project-dag.py', '--cfg-path', '/tmp/tmpdhug68pm']
[2024-04-20T13:17:56.054+0000] {standard_task_runner.py:91} INFO - Job 4: Subtask create_profiles
[2024-04-20T13:17:56.086+0000] {task_command.py:426} INFO - Running <TaskInstance: profile_creation_dag.create_profiles manual__2024-04-20T13:17:53.069327+00:00 [running]> on host 2d50efa26926
[2024-04-20T13:17:56.151+0000] {taskinstance.py:2644} INFO - Exporting env vars: AIRFLOW_CTX_DAG_OWNER='***' AIRFLOW_CTX_DAG_ID='profile_creation_dag' AIRFLOW_CTX_TASK_ID='create_profiles' AIRFLOW_CTX_EXECUTION_DATE='2024-04-20T13:17:53.069327+00:00' AIRFLOW_CTX_TRY_NUMBER='1' AIRFLOW_CTX_DAG_RUN_ID='manual__2024-04-20T13:17:53.069327+00:00'
[2024-04-20T13:17:56.152+0000] {taskinstance.py:430} INFO - ::endgroup::
[2024-04-20T13:17:56.156+0000] {taskinstance.py:441} INFO - ::group::Post task execution logs
[2024-04-20T13:17:56.156+0000] {taskinstance.py:2890} ERROR - Task failed with exception
Traceback (most recent call last):
  File "/home/airflow/.local/lib/python3.12/site-packages/airflow/models/taskinstance.py", line 465, in _execute_task
    result = _execute_callable(context=context, **execute_callable_kwargs)
             ^^^^^^^^^^^^^^^^^^^^^^^^^^^^^^^^^^^^^^^^^^^^^^^^^^^^^^^^^^^^^
  File "/home/airflow/.local/lib/python3.12/site-packages/airflow/models/taskinstance.py", line 432, in _execute_callable
    return execute_callable(context=context, **execute_callable_kwargs)
           ^^^^^^^^^^^^^^^^^^^^^^^^^^^^^^^^^^^^^^^^^^^^^^^^^^^^^^^^^^^^
  File "/home/airflow/.local/lib/python3.12/site-packages/airflow/models/baseoperator.py", line 400, in wrapper
    return func(self, *args, **kwargs)
           ^^^^^^^^^^^^^^^^^^^^^^^^^^^
  File "/home/airflow/.local/lib/python3.12/site-packages/airflow/operators/python.py", line 235, in execute
    return_value = self.execute_callable()
                   ^^^^^^^^^^^^^^^^^^^^^^^
  File "/home/airflow/.local/lib/python3.12/site-packages/airflow/operators/python.py", line 252, in execute_callable
    return self.python_callable(*self.op_args, **self.op_kwargs)
           ^^^^^^^^^^^^^^^^^^^^^^^^^^^^^^^^^^^^^^^^^^^^^^^^^^^^^
  File "/opt/airflow/dags/sample-project-dag.py", line 27, in profile_creation
    main()
  File "/opt/airflow/dags/scripts/superstore_script.py", line 64, in main
    conn = sqlite3.connect('/Users/ishaandawra/Desktop/Airflow_Project/dags/data/Retail_data.db')
           ^^^^^^^^^^^^^^^^^^^^^^^^^^^^^^^^^^^^^^^^^^^^^^^^^^^^^^^^^^^^^^^^^^^^^^^^^^^^^^^^^^^^^^
sqlite3.OperationalError: unable to open database file
[2024-04-20T13:17:56.164+0000] {taskinstance.py:1205} INFO - Marking task as FAILED. dag_id=profile_creation_dag, task_id=create_profiles, execution_date=20240420T131753, start_date=20240420T131756, end_date=20240420T131756
[2024-04-20T13:17:56.171+0000] {standard_task_runner.py:110} ERROR - Failed to execute job 4 for task create_profiles (unable to open database file; 116)
[2024-04-20T13:17:56.196+0000] {local_task_job_runner.py:240} INFO - Task exited with return code 1
[2024-04-20T13:17:56.263+0000] {taskinstance.py:3482} INFO - 0 downstream tasks scheduled from follow-on schedule check
[2024-04-20T13:17:56.264+0000] {local_task_job_runner.py:222} INFO - ::endgroup::
