[2024-04-20T13:19:10.491+0000] {local_task_job_runner.py:120} INFO - ::group::Pre task execution logs
[2024-04-20T13:19:10.515+0000] {taskinstance.py:2073} INFO - Dependencies all met for dep_context=non-requeueable deps ti=<TaskInstance: profile_creation_dag.create_profiles manual__2024-04-20T13:19:08.170496+00:00 [queued]>
[2024-04-20T13:19:10.521+0000] {taskinstance.py:2073} INFO - Dependencies all met for dep_context=requeueable deps ti=<TaskInstance: profile_creation_dag.create_profiles manual__2024-04-20T13:19:08.170496+00:00 [queued]>
[2024-04-20T13:19:10.521+0000] {taskinstance.py:2303} INFO - Starting attempt 1 of 1
[2024-04-20T13:19:10.528+0000] {taskinstance.py:2327} INFO - Executing <Task(PythonOperator): create_profiles> on 2024-04-20 13:19:08.170496+00:00
[2024-04-20T13:19:10.535+0000] {warnings.py:110} WARNING - /home/***/.local/lib/python3.12/site-packages/***/task/task_runner/standard_task_runner.py:61: DeprecationWarning: This process (pid=131) is multi-threaded, use of fork() may lead to deadlocks in the child.
  pid = os.fork()

[2024-04-20T13:19:10.536+0000] {standard_task_runner.py:90} INFO - Running: ['***', 'tasks', 'run', 'profile_creation_dag', 'create_profiles', 'manual__2024-04-20T13:19:08.170496+00:00', '--job-id', '5', '--raw', '--subdir', 'DAGS_FOLDER/sample-project-dag.py', '--cfg-path', '/tmp/tmp7dyy4lxv']
[2024-04-20T13:19:10.537+0000] {standard_task_runner.py:63} INFO - Started process 133 to run task
[2024-04-20T13:19:10.537+0000] {standard_task_runner.py:91} INFO - Job 5: Subtask create_profiles
[2024-04-20T13:19:10.566+0000] {task_command.py:426} INFO - Running <TaskInstance: profile_creation_dag.create_profiles manual__2024-04-20T13:19:08.170496+00:00 [running]> on host 2d50efa26926
[2024-04-20T13:19:10.604+0000] {taskinstance.py:2644} INFO - Exporting env vars: AIRFLOW_CTX_DAG_OWNER='***' AIRFLOW_CTX_DAG_ID='profile_creation_dag' AIRFLOW_CTX_TASK_ID='create_profiles' AIRFLOW_CTX_EXECUTION_DATE='2024-04-20T13:19:08.170496+00:00' AIRFLOW_CTX_TRY_NUMBER='1' AIRFLOW_CTX_DAG_RUN_ID='manual__2024-04-20T13:19:08.170496+00:00'
[2024-04-20T13:19:10.605+0000] {taskinstance.py:430} INFO - ::endgroup::
[2024-04-20T13:19:10.690+0000] {taskinstance.py:441} INFO - ::group::Post task execution logs
[2024-04-20T13:19:10.691+0000] {taskinstance.py:2890} ERROR - Task failed with exception
Traceback (most recent call last):
  File "/home/airflow/.local/lib/python3.12/site-packages/pandas/io/sql.py", line 2262, in execute
    cur.execute(sql, *args)
sqlite3.OperationalError: no such column: ranknumber

The above exception was the direct cause of the following exception:

Traceback (most recent call last):
  File "/home/airflow/.local/lib/python3.12/site-packages/airflow/models/taskinstance.py", line 465, in _execute_task
    result = _execute_callable(context=context, **execute_callable_kwargs)
             ^^^^^^^^^^^^^^^^^^^^^^^^^^^^^^^^^^^^^^^^^^^^^^^^^^^^^^^^^^^^^
  File "/home/airflow/.local/lib/python3.12/site-packages/airflow/models/taskinstance.py", line 432, in _execute_callable
    return execute_callable(context=context, **execute_callable_kwargs)
           ^^^^^^^^^^^^^^^^^^^^^^^^^^^^^^^^^^^^^^^^^^^^^^^^^^^^^^^^^^^^
  File "/home/airflow/.local/lib/python3.12/site-packages/airflow/models/baseoperator.py", line 400, in wrapper
    return func(self, *args, **kwargs)
           ^^^^^^^^^^^^^^^^^^^^^^^^^^^
  File "/home/airflow/.local/lib/python3.12/site-packages/airflow/operators/python.py", line 235, in execute
    return_value = self.execute_callable()
                   ^^^^^^^^^^^^^^^^^^^^^^^
  File "/home/airflow/.local/lib/python3.12/site-packages/airflow/operators/python.py", line 252, in execute_callable
    return self.python_callable(*self.op_args, **self.op_kwargs)
           ^^^^^^^^^^^^^^^^^^^^^^^^^^^^^^^^^^^^^^^^^^^^^^^^^^^^^
  File "/opt/airflow/dags/sample-project-dag.py", line 27, in profile_creation
    main()
  File "/opt/airflow/dags/scripts/superstore_script.py", line 94, in main
    dataframes = [execute_query(conn, q) for q in queries]
                  ^^^^^^^^^^^^^^^^^^^^^^
  File "/opt/airflow/dags/scripts/superstore_script.py", line 11, in execute_query
    return pd.read_sql_query(query, conn)
           ^^^^^^^^^^^^^^^^^^^^^^^^^^^^^^
  File "/home/airflow/.local/lib/python3.12/site-packages/pandas/io/sql.py", line 486, in read_sql_query
    return pandas_sql.read_query(
           ^^^^^^^^^^^^^^^^^^^^^^
  File "/home/airflow/.local/lib/python3.12/site-packages/pandas/io/sql.py", line 2326, in read_query
    cursor = self.execute(sql, params)
             ^^^^^^^^^^^^^^^^^^^^^^^^^
  File "/home/airflow/.local/lib/python3.12/site-packages/pandas/io/sql.py", line 2274, in execute
    raise ex from exc
pandas.errors.DatabaseError: Execution failed on sql 'SELECT CUSTOMER_ID,CATEGORY as Prefered_category,SUB_CATEGORY as prefered_sub_category FROM (SELECT CUSTOMER_ID,CATEGORY,SUB_CATEGORY,ROW_NUMBER() OVER(PARTITION BY CUSTOMER_ID ORDER BY COUNT(*) DESC) as randknumber FROM  Retail_data GROUP BY  CUSTOMER_ID, CATEGORY, SUB_CATEGORY) AS temp WHERE ranknumber = 1 ORDER BY CUSTOMER_ID;': no such column: ranknumber
[2024-04-20T13:19:10.701+0000] {taskinstance.py:1205} INFO - Marking task as FAILED. dag_id=profile_creation_dag, task_id=create_profiles, execution_date=20240420T131908, start_date=20240420T131910, end_date=20240420T131910
[2024-04-20T13:19:10.707+0000] {standard_task_runner.py:110} ERROR - Failed to execute job 5 for task create_profiles (Execution failed on sql 'SELECT CUSTOMER_ID,CATEGORY as Prefered_category,SUB_CATEGORY as prefered_sub_category FROM (SELECT CUSTOMER_ID,CATEGORY,SUB_CATEGORY,ROW_NUMBER() OVER(PARTITION BY CUSTOMER_ID ORDER BY COUNT(*) DESC) as randknumber FROM  Retail_data GROUP BY  CUSTOMER_ID, CATEGORY, SUB_CATEGORY) AS temp WHERE ranknumber = 1 ORDER BY CUSTOMER_ID;': no such column: ranknumber; 133)
[2024-04-20T13:19:10.720+0000] {local_task_job_runner.py:240} INFO - Task exited with return code 1
[2024-04-20T13:19:10.728+0000] {taskinstance.py:3482} INFO - 0 downstream tasks scheduled from follow-on schedule check
[2024-04-20T13:19:10.729+0000] {local_task_job_runner.py:222} INFO - ::endgroup::
