[2024-04-20T13:02:29.954+0000] {local_task_job_runner.py:120} INFO - ::group::Pre task execution logs
[2024-04-20T13:02:29.966+0000] {taskinstance.py:2073} INFO - Dependencies all met for dep_context=non-requeueable deps ti=<TaskInstance: profile_creation_dag.create_profiles manual__2024-04-20T13:02:28.628920+00:00 [queued]>
[2024-04-20T13:02:29.970+0000] {taskinstance.py:2073} INFO - Dependencies all met for dep_context=requeueable deps ti=<TaskInstance: profile_creation_dag.create_profiles manual__2024-04-20T13:02:28.628920+00:00 [queued]>
[2024-04-20T13:02:29.971+0000] {taskinstance.py:2303} INFO - Starting attempt 1 of 1
[2024-04-20T13:02:29.976+0000] {taskinstance.py:2327} INFO - Executing <Task(PythonOperator): create_profiles> on 2024-04-20 13:02:28.628920+00:00
[2024-04-20T13:02:29.984+0000] {warnings.py:110} WARNING - /home/***/.local/lib/python3.12/site-packages/***/task/task_runner/standard_task_runner.py:61: DeprecationWarning: This process (pid=142) is multi-threaded, use of fork() may lead to deadlocks in the child.
  pid = os.fork()

[2024-04-20T13:02:29.986+0000] {standard_task_runner.py:63} INFO - Started process 144 to run task
[2024-04-20T13:02:29.985+0000] {standard_task_runner.py:90} INFO - Running: ['***', 'tasks', 'run', 'profile_creation_dag', 'create_profiles', 'manual__2024-04-20T13:02:28.628920+00:00', '--job-id', '6', '--raw', '--subdir', 'DAGS_FOLDER/sample-project-dag.py', '--cfg-path', '/tmp/tmpozo8mqd3']
[2024-04-20T13:02:29.986+0000] {standard_task_runner.py:91} INFO - Job 6: Subtask create_profiles
[2024-04-20T13:02:30.010+0000] {task_command.py:426} INFO - Running <TaskInstance: profile_creation_dag.create_profiles manual__2024-04-20T13:02:28.628920+00:00 [running]> on host 670df62afafc
[2024-04-20T13:02:30.058+0000] {taskinstance.py:2644} INFO - Exporting env vars: AIRFLOW_CTX_DAG_OWNER='***' AIRFLOW_CTX_DAG_ID='profile_creation_dag' AIRFLOW_CTX_TASK_ID='create_profiles' AIRFLOW_CTX_EXECUTION_DATE='2024-04-20T13:02:28.628920+00:00' AIRFLOW_CTX_TRY_NUMBER='1' AIRFLOW_CTX_DAG_RUN_ID='manual__2024-04-20T13:02:28.628920+00:00'
[2024-04-20T13:02:30.060+0000] {taskinstance.py:430} INFO - ::endgroup::
[2024-04-20T13:02:30.060+0000] {taskinstance.py:441} INFO - ::group::Post task execution logs
[2024-04-20T13:02:30.061+0000] {taskinstance.py:2890} ERROR - Task failed with exception
Traceback (most recent call last):
  File "/home/airflow/.local/lib/python3.12/site-packages/airflow/models/taskinstance.py", line 465, in _execute_task
    result = _execute_callable(context=context, **execute_callable_kwargs)
             ^^^^^^^^^^^^^^^^^^^^^^^^^^^^^^^^^^^^^^^^^^^^^^^^^^^^^^^^^^^^^
  File "/home/airflow/.local/lib/python3.12/site-packages/airflow/models/taskinstance.py", line 432, in _execute_callable
    return execute_callable(context=context, **execute_callable_kwargs)
           ^^^^^^^^^^^^^^^^^^^^^^^^^^^^^^^^^^^^^^^^^^^^^^^^^^^^^^^^^^^^
  File "/home/airflow/.local/lib/python3.12/site-packages/airflow/models/baseoperator.py", line 400, in wrapper
    return func(self, *args, **kwargs)
           ^^^^^^^^^^^^^^^^^^^^^^^^^^^
  File "/home/airflow/.local/lib/python3.12/site-packages/airflow/operators/python.py", line 235, in execute
    return_value = self.execute_callable()
                   ^^^^^^^^^^^^^^^^^^^^^^^
  File "/home/airflow/.local/lib/python3.12/site-packages/airflow/operators/python.py", line 252, in execute_callable
    return self.python_callable(*self.op_args, **self.op_kwargs)
           ^^^^^^^^^^^^^^^^^^^^^^^^^^^^^^^^^^^^^^^^^^^^^^^^^^^^^
  File "/opt/airflow/dags/sample-project-dag.py", line 27, in profile_creation
    main()
  File "/opt/airflow/dags/scripts/superstore_script.py", line 64, in main
    conn = sqlite3.connect('/Users/ishaandawra/Desktop/Airflow_Project/dags/data/Retail_data.db')
           ^^^^^^^^^^^^^^^^^^^^^^^^^^^^^^^^^^^^^^^^^^^^^^^^^^^^^^^^^^^^^^^^^^^^^^^^^^^^^^^^^^^^^^
sqlite3.OperationalError: unable to open database file
[2024-04-20T13:02:30.065+0000] {taskinstance.py:1205} INFO - Marking task as FAILED. dag_id=profile_creation_dag, task_id=create_profiles, execution_date=20240420T130228, start_date=20240420T130229, end_date=20240420T130230
[2024-04-20T13:02:30.070+0000] {standard_task_runner.py:110} ERROR - Failed to execute job 6 for task create_profiles (unable to open database file; 144)
[2024-04-20T13:02:30.090+0000] {local_task_job_runner.py:240} INFO - Task exited with return code 1
[2024-04-20T13:02:30.098+0000] {taskinstance.py:3482} INFO - 0 downstream tasks scheduled from follow-on schedule check
[2024-04-20T13:02:30.099+0000] {local_task_job_runner.py:222} INFO - ::endgroup::
