[2024-04-20T13:13:57.216+0000] {local_task_job_runner.py:120} INFO - ::group::Pre task execution logs
[2024-04-20T13:13:57.227+0000] {taskinstance.py:2073} INFO - Dependencies all met for dep_context=non-requeueable deps ti=<TaskInstance: profile_creation_dag.create_profiles manual__2024-04-20T13:13:54.404241+00:00 [queued]>
[2024-04-20T13:13:57.230+0000] {taskinstance.py:2073} INFO - Dependencies all met for dep_context=requeueable deps ti=<TaskInstance: profile_creation_dag.create_profiles manual__2024-04-20T13:13:54.404241+00:00 [queued]>
[2024-04-20T13:13:57.230+0000] {taskinstance.py:2303} INFO - Starting attempt 1 of 1
[2024-04-20T13:13:57.235+0000] {taskinstance.py:2327} INFO - Executing <Task(PythonOperator): create_profiles> on 2024-04-20 13:13:54.404241+00:00
[2024-04-20T13:13:57.240+0000] {warnings.py:110} WARNING - /home/***/.local/lib/python3.12/site-packages/***/task/task_runner/standard_task_runner.py:61: DeprecationWarning: This process (pid=56) is multi-threaded, use of fork() may lead to deadlocks in the child.
  pid = os.fork()

[2024-04-20T13:13:57.242+0000] {standard_task_runner.py:63} INFO - Started process 58 to run task
[2024-04-20T13:13:57.242+0000] {standard_task_runner.py:90} INFO - Running: ['***', 'tasks', 'run', 'profile_creation_dag', 'create_profiles', 'manual__2024-04-20T13:13:54.404241+00:00', '--job-id', '3', '--raw', '--subdir', 'DAGS_FOLDER/sample-project-dag.py', '--cfg-path', '/tmp/tmp036spz7l']
[2024-04-20T13:13:57.243+0000] {standard_task_runner.py:91} INFO - Job 3: Subtask create_profiles
[2024-04-20T13:13:57.266+0000] {task_command.py:426} INFO - Running <TaskInstance: profile_creation_dag.create_profiles manual__2024-04-20T13:13:54.404241+00:00 [running]> on host 2d50efa26926
[2024-04-20T13:13:57.319+0000] {taskinstance.py:2644} INFO - Exporting env vars: AIRFLOW_CTX_DAG_OWNER='***' AIRFLOW_CTX_DAG_ID='profile_creation_dag' AIRFLOW_CTX_TASK_ID='create_profiles' AIRFLOW_CTX_EXECUTION_DATE='2024-04-20T13:13:54.404241+00:00' AIRFLOW_CTX_TRY_NUMBER='1' AIRFLOW_CTX_DAG_RUN_ID='manual__2024-04-20T13:13:54.404241+00:00'
[2024-04-20T13:13:57.320+0000] {taskinstance.py:430} INFO - ::endgroup::
[2024-04-20T13:13:57.372+0000] {taskinstance.py:441} INFO - ::group::Post task execution logs
[2024-04-20T13:13:57.372+0000] {taskinstance.py:2890} ERROR - Task failed with exception
Traceback (most recent call last):
  File "/home/airflow/.local/lib/python3.12/site-packages/pandas/io/sql.py", line 2262, in execute
    cur.execute(sql, *args)
sqlite3.OperationalError: near ";": syntax error

The above exception was the direct cause of the following exception:

Traceback (most recent call last):
  File "/home/airflow/.local/lib/python3.12/site-packages/airflow/models/taskinstance.py", line 465, in _execute_task
    result = _execute_callable(context=context, **execute_callable_kwargs)
             ^^^^^^^^^^^^^^^^^^^^^^^^^^^^^^^^^^^^^^^^^^^^^^^^^^^^^^^^^^^^^
  File "/home/airflow/.local/lib/python3.12/site-packages/airflow/models/taskinstance.py", line 432, in _execute_callable
    return execute_callable(context=context, **execute_callable_kwargs)
           ^^^^^^^^^^^^^^^^^^^^^^^^^^^^^^^^^^^^^^^^^^^^^^^^^^^^^^^^^^^^
  File "/home/airflow/.local/lib/python3.12/site-packages/airflow/models/baseoperator.py", line 400, in wrapper
    return func(self, *args, **kwargs)
           ^^^^^^^^^^^^^^^^^^^^^^^^^^^
  File "/home/airflow/.local/lib/python3.12/site-packages/airflow/operators/python.py", line 235, in execute
    return_value = self.execute_callable()
                   ^^^^^^^^^^^^^^^^^^^^^^^
  File "/home/airflow/.local/lib/python3.12/site-packages/airflow/operators/python.py", line 252, in execute_callable
    return self.python_callable(*self.op_args, **self.op_kwargs)
           ^^^^^^^^^^^^^^^^^^^^^^^^^^^^^^^^^^^^^^^^^^^^^^^^^^^^^
  File "/opt/airflow/dags/sample-project-dag.py", line 27, in profile_creation
    main()
  File "/opt/airflow/dags/scripts/superstore_script.py", line 94, in main
    dataframes = [execute_query(conn, q) for q in queries]
                  ^^^^^^^^^^^^^^^^^^^^^^
  File "/opt/airflow/dags/scripts/superstore_script.py", line 11, in execute_query
    return pd.read_sql_query(query, conn)
           ^^^^^^^^^^^^^^^^^^^^^^^^^^^^^^
  File "/home/airflow/.local/lib/python3.12/site-packages/pandas/io/sql.py", line 486, in read_sql_query
    return pandas_sql.read_query(
           ^^^^^^^^^^^^^^^^^^^^^^
  File "/home/airflow/.local/lib/python3.12/site-packages/pandas/io/sql.py", line 2326, in read_query
    cursor = self.execute(sql, params)
             ^^^^^^^^^^^^^^^^^^^^^^^^^
  File "/home/airflow/.local/lib/python3.12/site-packages/pandas/io/sql.py", line 2274, in execute
    raise ex from exc
pandas.errors.DatabaseError: Execution failed on sql 'SELECT CUSTOMER_ID, SUM(SALES) AS Total_Sales, SUM(Profit) AS Total_Loss FROM Retail_data WHERE  CUSTOMER_ID NOT IN (SELECT DISTINCT CUSTOMER_ID FROM Retail_data WHERE Profit > 0 GROUP BY CUSTOMER_ID;': near ";": syntax error
[2024-04-20T13:13:57.384+0000] {taskinstance.py:1205} INFO - Marking task as FAILED. dag_id=profile_creation_dag, task_id=create_profiles, execution_date=20240420T131354, start_date=20240420T131357, end_date=20240420T131357
[2024-04-20T13:13:57.390+0000] {standard_task_runner.py:110} ERROR - Failed to execute job 3 for task create_profiles (Execution failed on sql 'SELECT CUSTOMER_ID, SUM(SALES) AS Total_Sales, SUM(Profit) AS Total_Loss FROM Retail_data WHERE  CUSTOMER_ID NOT IN (SELECT DISTINCT CUSTOMER_ID FROM Retail_data WHERE Profit > 0 GROUP BY CUSTOMER_ID;': near ";": syntax error; 58)
[2024-04-20T13:13:57.426+0000] {local_task_job_runner.py:240} INFO - Task exited with return code 1
[2024-04-20T13:13:57.445+0000] {taskinstance.py:3482} INFO - 0 downstream tasks scheduled from follow-on schedule check
[2024-04-20T13:13:57.448+0000] {local_task_job_runner.py:222} INFO - ::endgroup::
